{
  "_annotation": {
    "cve_id": "CVE-2024-28179",
    "generated_from": "https://raw.githubusercontent.com/anchore/cve-data-enrichment/main/data/anchore/2024/CVE-2024-28179.json",
    "reason": "Added CPE configurations because not yet analyzed by NVD."
  },
  "cve": {
    "configurations": [
      {
        "nodes": [
          {
            "cpeMatch": [
              {
                "criteria": "cpe:2.3:a:jupyter:jupyter_server_proxy:*:*:*:*:*:python:*:*",
                "matchCriteriaId": "D770E63E-B657-5F2B-8B00-D367BCFD7FB4",
                "versionEndExcluding": "4.1.1",
                "versionStartIncluding": "4.0.0",
                "vulnerable": true
              },
              {
                "criteria": "cpe:2.3:a:jupyter:jupyter_server_proxy:*:*:*:*:*:python:*:*",
                "matchCriteriaId": "C67D1BE9-E3C3-5A02-8CB3-D3E9112D0C5A",
                "versionEndExcluding": "3.2.3",
                "vulnerable": true
              }
            ],
            "negate": false,
            "operator": "OR"
          }
        ]
      }
    ]
  }
}