{
  "_annotation": {
    "cve_id": "CVE-2024-35178",
    "generated_from": "https://raw.githubusercontent.com/anchore/cve-data-enrichment/main/data/anchore/2024/CVE-2024-35178.json",
    "reason": "Added CPE configurations because not yet analyzed by NVD."
  },
  "cve": {
    "configurations": [
      {
        "nodes": [
          {
            "cpeMatch": [
              {
                "criteria": "cpe:2.3:a:jupyter:jupyter_server:*:*:*:*:*:python:*:*",
                "matchCriteriaId": "3BE2A451-B10A-5958-A934-32EAC00F80BC",
                "versionEndExcluding": "2.14.1",
                "vulnerable": true
              }
            ],
            "negate": false,
            "operator": "OR"
          }
        ]
      }
    ]
  }
}